Workbook

Sheet Cover
B6: Financial Statement Analysis
B12: Tesla
B13: =TODAY() -> 46284
B24: Financial Model Solution - Vertical Orientation | H24: Powered by: | I24: Xinjian Tan

Sheet Assumptions
B1: =Summary!B1 -> Tesla
B2: Inputs and Assumptions
C5: GENERAL | J5: EQUITY
C8: - | D8: First year of forecast in financial model: | G8: 2026 | J8: ="Stock Price - "&TEXT(TODAY()-1,"mm/dd/yy") -> Stock Price - 09/18/26 | N8: 366.98
C9: - | D9: Three scenarios have been used for Inflation, Product Pricing | J9: ="Fully Diluted Shares O/S (MM) - Dec. 31, "&G8-1 -> Fully Diluted Shares O/S (MM) - Dec. 31, 2025 | N9: 3752.4
D10: and sales volume growth | J10: Common Dividend Payout Rate | N10: 0
C13: PRODUCT PRICING | J13: OPERATIONS
C16: - | D16: The product pricing cases used in the model are as follows:
C17: Pricing Case | E17: =Scenarios!G6&" - "&Scenarios!K6 -> 2026 - 2030 | J17: Annual Factory Capacity (000's units): | N17: 2350
C18: Base Case | E18: Research Forecast | J18: Restructuring & Other | N18: 0
C19: Best Case | F19: 0.04
C20: Worst Case | F20: -0.04
C23: COSTS | J23: INTEREST RATES
C26: Cost Item | E26: =G8 -> 2026 | G26: Increases
C27: Raw Materials | E27: 29000 | F27: per Unit | G27: Inflation on a unit basis | J27: Interest earned on Cash balances: | N27: 0.042
C28: Utilities | E28: 1500 | F28: per Unit | G28: Inflation on a unit basis | J28: Interest rate on Bank Revolver: | N28: 0.055
C29: Rent | E29: 1500 | F29: MM | G29: Inflation on a total basis | J29: Interest rate on Senior Secured Term Debt: | N29: 0.055
C30: Operating Labour | E30: 4500 | F30: MM | G30: Inflation on a total basis
C31: Other | E31: 500 | F31: MM | G31: Inflation on a total basis
C32: SG&A | E32: 5834 | F32: MM | G32: Inflation on a total basis
C35: DEPRECIATION | J35: TAXES
C38: - | D38: Depreciation Methodology Used: | H38: Straight Line
C39: - | D39: Years remaining for depreciation of existing assets: | H39: 15 | J39: Tax rate assumed in the model: | N39: 0.27
C40: - | D40: Years used for depreciation of new assets: | H40: 15 | J40: Additional tax assumptions in "Other Assumptions" box
B44: =Summary!B1 -> Tesla
B45: Inputs and Assumptions
C48: OTHER ASSUMPTIONS | J48: =G8 -> 2026 | K48: =J48+1 -> 2027 | L48: =K48+1 -> 2028 | M48: =L48+1 -> 2029 | N48: =M48+1 -> 2030
C52: Income Statement
D53: Cost Adjustments - Gain/(Loss) | G53: MM | J53: 0 | K53: 0 | L53: 0 | M53: 0 | N53: 0
C55: Cash Flow Statement
D56: Investing Activities - Other | G56: MM | J56: 0 | K56: 0 | L56: 0 | M56: 0 | N56: 0
C58: Capital Expenditures | G58: MM | J58: 25500 | K58: 20000 | L58: 18500 | M58: 18500 | N58: 18500
C60: Income Tax
D61: Reduction in EBT for timing differences | G61: MM | J61: 100 | K61: 100 | L61: 100 | M61: 100 | N61: 100
C63: Working Capital Days
D64: Accounts Receivable | G64: days | J64: 18 | K64: 18 | L64: 17 | M64: 17 | N64: 17
D65: Inventories | G65: days | J65: 58 | K65: 57 | L65: 55 | M65: 55 | N65: 55
D66: Prepaid Expenses | G66: days | J66: 36 | K66: 36 | L66: 36 | M66: 36 | N66: 36
D67: Other Assets | G67: days | J67: 3 | K67: 3 | L67: 3 | M67: 3 | N67: 3
D68: Accounts Payable | G68: days | J68: 63 | K68: 62 | L68: 60 | M68: 58 | N68: 57
...

Sheet Scenarios
B1: =Assumptions!B1 -> Tesla
B2: Economic and Sales Scenarios
B6: SCENARIO SWITCH: | D6: 3 | G6: =Assumptions!G8 -> 2026 | H6: =G6+1 -> 2027 | I6: =H6+1 -> 2028 | J6: =I6+1 -> 2029 | K6: =J6+1 -> 2030
B10: ECONOMIC SCENARIOS
B12: Cost Inflation | G12: =CHOOSE($D$6,G14,G15,G16) -> 0.028 | H12: =CHOOSE($D$6,H14,H15,H16) -> 0.028 | I12: =CHOOSE($D$6,I14,I15,I16) -> 0.028 | J12: =CHOOSE($D$6,J14,J15,J16) -> 0.028 | K12: =CHOOSE($D$6,K14,K15,K16) -> 0.028
C14: =Assumptions!C18 -> Base Case | G14: 0.02 | H14: 0.02 | I14: 0.02 | J14: 0.022 | K14: 0.022
C15: =Assumptions!C19 -> Best Case | G15: 0.015 | H15: 0.015 | I15: 0.015 | J15: 0.017 | K15: 0.017
C16: =Assumptions!C20 -> Worst Case | G16: 0.028 | H16: 0.028 | I16: 0.028 | J16: 0.028 | K16: 0.028
B21: SALES SCENARIOS
B23: Sales Price - $/Unit | G23: =CHOOSE($D$6,G25,G26,G27) -> 40800 | H23: =CHOOSE($D$6,H25,H26,H27) -> 40800 | I23: =CHOOSE($D$6,I25,I26,I27) -> 40800 | J23: =CHOOSE($D$6,J25,J26,J27) -> 40800 | K23: =CHOOSE($D$6,K25,K26,K27) -> 40800
C25: =C14 -> Base Case | G25: 42500 | H25: 42500 | I25: 42500 | J25: 42500 | K25: 42500
A26: =Assumptions!F19 -> 0.04 | C26: =CONCATENATE(C15,": ",TEXT(A26,"+0.0%;-0.0%")) -> Best Case: +4.0% | G26: =G$25*(1+$A26) -> 44200 | H26: =H$25*(1+$A26) -> 44200 | I26: =I$25*(1+$A26) -> 44200 | J26: =J$25*(1+$A26) -> 44200 | K26: =K$25*(1+$A26) -> 44200
A27: =Assumptions!F20 -> -0.04 | C27: =CONCATENATE(C16,": ",TEXT(A27,"+0.0%;-0.0%")) -> Worst Case: -4.0% | G27: =G$25*(1+$A27) -> 40800 | H27: =H$25*(1+$A27) -> 40800 | I27: =I$25*(1+$A27) -> 40800 | J27: =J$25*(1+$A27) -> 40800 | K27: =K$25*(1+$A27) -> 40800
B30: Sales Volume Growth | G30: =CHOOSE($D$6,G32,G33,G34) -> 0.01 | H30: =CHOOSE($D$6,H32,H33,H34) -> 0.02 | I30: =CHOOSE($D$6,I32,I33,I34) -> 0.01 | J30: =CHOOSE($D$6,J32,J33,J34) -> 0.01 | K30: =CHOOSE($D$6,K32,K33,K34) -> 0.02
C32: =C14 -> Base Case | G32: 0.02 | H32: 0.05 | I32: 0.07 | J32: 0.07 | K32: 0.06
C33: =C15 -> Best Case | G33: 0.05 | H33: 0.08 | I33: 0.1 | J33: 0.1 | K33: 0.08
C34: =C16 -> Worst Case | G34: 0.01 | H34: 0.02 | I34: 0.01 | J34: 0.01 | K34: 0.02

Sheet Model
O1: ="CURRENTLY RUNNING: "&UPPER(CHOOSE(Scenarios!$D$6,Scenarios!C14,Scenarios!C15,Scenarios!C16))&" SCENARIO" -> CURRENTLY RUNNING: WORST CASE SCENARIO
B2: =Scenarios!B1 -> Tesla
B3: Revenue Schedule
K6: Projected
H7: =I7-1 -> 2023 | I7: =J7-1 -> 2024 | J7: =K7-1 -> 2025 | K7: =Scenarios!G6 -> 2026 | L7: =Scenarios!H6 -> 2027 | M7: =Scenarios!I6 -> 2028 | N7: =Scenarios!J6 -> 2029 | O7: =Scenarios!K6 -> 2030
B9: Pricing
C10: Gross Sales Price | F10: ($/unit) | J10: 40230 | K10: =Scenarios!G23 -> 40800 | L10: =Scenarios!H23 -> 40800 | M10: =Scenarios!I23 -> 40800 | N10: =Scenarios!J23 -> 40800 | O10: =Scenarios!K23 -> 40800
C11: Cost Inflation | F11: (%) | K11: =Scenarios!G12 -> 0.028 | L11: =Scenarios!H12 -> 0.028 | M11: =Scenarios!I12 -> 0.028 | N11: =Scenarios!J12 -> 0.028 | O11: =Scenarios!K12 -> 0.028
C12: Freight & Warehousing | F12: ($/unit) | J12: 0 | K12: =J12*(1+K$11) -> 0 | L12: =K12*(1+L$11) -> 0 | M12: =L12*(1+M$11) -> 0 | N12: =M12*(1+N$11) -> 0 | O12: =N12*(1+O$11) -> 0
C13: Net Sales Price | F13: ($/unit) | J13: =J10-J12 -> 40230 | K13: =K10-K12 -> 40800 | L13: =L10-L12 -> 40800 | M13: =M10-M12 -> 40800 | N13: =N10-N12 -> 40800 | O13: =O10-O12 -> 40800
B16: Sales Volume
C17: Annual Factory Capacity | F17: (000's units) | K17: =Assumptions!N17 -> 2350 | L17: =K17 -> 2350 | M17: =L17 -> 2350 | N17: =M17 -> 2350 | O17: =N17 -> 2350
C19: Sales Volume Growth | F19: (%) | K19: =Scenarios!G30 -> 0.01 | L19: =Scenarios!H30 -> 0.02 | M19: =Scenarios!I30 -> 0.01 | N19: =Scenarios!J30 -> 0.01 | O19: =Scenarios!K30 -> 0.02
C20: Annual Sales Volume | F20: (000's units) | J20: =+J26*1000/J10 -> 1636.1173 | K20: =MIN(K17,J20*(1+K19)) -> 1652.4785 | L20: =MIN(L17,K20*(1+L19)) -> 1685.5281 | M20: =MIN(M17,L20*(1+M19)) -> 1702.3833 | N20: =MIN(N17,M20*(1+N19)) -> 1719.4072 | O20: =MIN(O17,N20*(1+O19)) -> 1753.7953
C22: Implied Operating Rate | K22: =K20/K17 -> 0.70318234 | L22: =L20/L17 -> 0.71724599 | M22: =M20/M17 -> 0.72441845 | N22: =N20/N17 -> 0.73166263 | O22: =O20/O17 -> 0.74629588
B25: Revenue
C26: Gross Revenue | F26: ($ MM) | J26: =+J84 -> 65821 | K26: =K$20*K10/1000 -> 67421.123 | L26: =L$20*L10/1000 -> 68769.545 | M26: =M$20*M10/1000 -> 69457.241 | N26: =N$20*N10/1000 -> 70151.813 | O26: =O$20*O10/1000 -> 71554.849
C27: Freight & Warehousing | F27: ($ MM) | J27: =+J85 -> 0 | K27: =K$20*K12/1000 -> 0 | L27: =L$20*L12/1000 -> 0 | M27: =M$20*M12/1000 -> 0 | N27: =N$20*N12/1000 -> 0 | O27: =O$20*O12/1000 -> 0
C28: Others (Aggregrate) | F28: ($ MM) | J28: =J86 -> 29006 | K28: =J28*(1+5%) -> 30456.3 | L28: =K28*(1+5%) -> 31979.115 | M28: =L28*(1+5%) -> 33578.071 | N28: =M28*(1+5%) -> 35256.974 | O28: =N28*(1+5%) -> 37019.823
C29: Net Revenue | F29: ($ MM) | J29: =J26-J27+J28 -> 94827 | K29: =K26-K27+K28 -> 97877.423 | L29: =L26-L27+L28 -> 100748.66 | M29: =M26-M27+M28 -> 103035.31 | N29: =N26-N27+N28 -> 105408.79 | O29: =O26-O27+O28 -> 108574.67
O32: =$O$1 -> CURRENTLY RUNNING: WORST CASE SCENARIO
B33: =B$2 -> Tesla
B34: Costs of Production Schedule
K37: Projected
H38: =H$7 -> 2023 | I38: =I$7 -> 2024 | J38: =J$7 -> 2025 | K38: =K$7 -> 2026 | L38: =L$7 -> 2027 | M38: =M$7 -> 2028 | N38: =N$7 -> 2029 | O38: =O$7 -> 2030
B40: Annual Sales Volume | F40: (000's units) | J40: =J20 -> 1636.1173 | K40: =K20 -> 1652.4785 | L40: =L20 -> 1685.5281 | M40: =M20 -> 1702.3833 | N40: =N20 -> 1719.4072 | O40: =O20 -> 1753.7953
B41: Cost Inflation | F41: (%) | L41: =L11 -> 0.028 | M41: =M11 -> 0.028 | N41: =N11 -> 0.028 | O41: =O11 -> 0.028
B43: COSTS PER UNIT
C44: Variable Costs
D45: =Assumptions!C27 -> Raw Materials | F45: ($/unit) | K45: =Assumptions!E27 -> 29000 | L45: =K45*(1+L$41) -> 29812 | M45: =L45*(1+M$41) -> 30646.736 | N45: =M45*(1+N$41) -> 31504.845 | O45: =N45*(1+O$41) -> 32386.98
D46: =Assumptions!C28 -> Utilities | F46: ($/unit) | K46: =Assumptions!E28 -> 1500 | L46: =K46*(1+L$41) -> 1542 | M46: =L46*(1+M$41) -> 1585.176 | N46: =M46*(1+N$41) -> 1629.5609 | O46: =N46*(1+O$41) -> 1675.1886
D47: Total Variable Costs | F47: ($/unit) | K47: =K46+K45 -> 30500 | L47: =L46+L45 -> 31354 | M47: =M46+M45 -> 32231.912 | N47: =N46+N45 -> 33134.406 | O47: =O46+O45 -> 34062.169
C49: Fixed Costs
D50: =Assumptions!C29 -> Rent | F50: ($/unit) | K50: =K65*1000/K$40 -> 907.72739 | L50: =L65*1000/L$40 -> 914.84682 | M50: =M65*1000/M$40 -> 931.15102 | N50: =N65*1000/N$40 -> 947.7458 | O50: =O65*1000/O$40 -> 955.1791
D51: =Assumptions!C30 -> Operating Labour | F51: ($/unit) | K51: =K66*1000/K$40 -> 2723.1822 | L51: =L66*1000/L$40 -> 2744.5405 | M51: =M66*1000/M$40 -> 2793.4531 | N51: =N66*1000/N$40 -> 2843.2374 | O51: =O66*1000/O$40 -> 2865.5373
D52: Other | F52: ($/unit) | K52: =K67*1000/K$40 -> 302.5758 | L52: =L67*1000/L$40 -> 304.94894 | M52: =M67*1000/M$40 -> 310.38367 | N52: =N67*1000/N$40 -> 315.91527 | O52: =O67*1000/O$40 -> 318.39303
D53: Total Fixed Costs | F53: ($/unit) | K53: =SUM(K50:K52) -> 3933.4854 | L53: =SUM(L50:L52) -> 3964.3362 | M53: =SUM(M50:M52) -> 4034.9878 | N53: =SUM(N50:N52) -> 4106.8984 | O53: =SUM(O50:O52) -> 4139.1094
C55: Total Costs-vehicle | F55: ($/unit) | K55: =K53+K47 -> 34433.485 | L55: =L53+L47 -> 35318.336 | M55: =M53+M47 -> 36266.9 | N55: =N53+N47 -> 37241.304 | O55: =O53+O47 -> 38201.278
B58: COSTS IN MILLIONS
C59: Variable Costs
...

Sheet Summary
B1: =Cover!B12 -> Tesla
B2: Summary Outputs
C5: SUMMARY VALUES - BASE CASE | T5: ="SUMMMARY VALUES - "&UPPER(CHOOSE(Scenarios!$D$6,Scenarios!C14,Scenarios!C15,Scenarios!C16)) -> SUMMMARY VALUES - WORST CASE
K6: Projected | AA6: Projected
D7: ($ Millions) | F7: Trend | H7: =X7 -> 2023 | I7: =Y7 -> 2024 | J7: =Z7 -> 2025 | K7: =AA7 -> 2026 | L7: =AB7 -> 2027 | M7: =AC7 -> 2028 | N7: =AD7 -> 2029 | O7: =AE7 -> 2030 | X7: =Model!H7 -> 2023 | Y7: =Model!I7 -> 2024 | Z7: =Model!J7 -> 2025 | AA7: =Model!K7 -> 2026 | AB7: =Model!L7 -> 2027 | AC7: =Model!M7 -> 2028 | AD7: =Model!N7 -> 2029 | AE7: =Model!O7 -> 2030
D10: Income Statement Items | U10: Income Statement Items
E12: Net Revenue | H12: 96773 | I12: 97690 | J12: 94827 | K12: 101381.99 | L12: 106451.09 | M12: 113263.08 | N12: 120519.93 | O12: 127398.56 | V12: Net Revenue | W12: (MM) | X12: =Model!H87 -> 96773 | Y12: =Model!I87 -> 97690 | Z12: =Model!J87 -> 94827 | AA12: =Model!K87 -> 97877.423 | AB12: =Model!L87 -> 100748.66 | AC12: =Model!M87 -> 103035.31 | AD12: =Model!N87 -> 105408.79 | AE12: =Model!O87 -> 108574.67
E13: Growth | I13: 0.0094757835 | J13: -0.029306992 | K13: 0.069125735 | L13: 0.05 | M13: 0.063991773 | N13: 0.064070783 | O13: 0.057074594 | V13: Growth | W13: (%) | Y13: =Y12/X12-1 -> 0.0094757835 | Z13: =Z12/Y12-1 -> -0.029306992 | AA13: =AA12/Z12-1 -> 0.032168293 | AB13: =AB12/AA12-1 -> 0.029335033 | AC13: =AC12/AB12-1 -> 0.022696592 | AD13: =AD12/AC12-1 -> 0.023035559 | AE13: =AE12/AD12-1 -> 0.030034355
E16: EBITDA | H16: 13558 | I16: 12444 | J16: 10503 | K16: 8556.9761 | L16: 7933.3481 | M16: 7552.1516 | N16: 6865.655 | O16: 5791.6175 | V16: EBITDA | W16: (MM) | X16: =Model!H97 -> 13558 | Y16: =Model!I97 -> 12444 | Z16: =Model!J97 -> 10503 | AA16: =Model!K97 -> 5551.4285 | AB16: =Model!L97 -> 3797.6861 | AC16: =Model!M97 -> 1747.248 | AD16: =Model!N97 -> -440.48612 | AE16: =Model!O97 -> -2659.5577
E17: Margin | H17: 0.14010106 | I17: 0.12738254 | J17: 0.11075959 | K17: 0.084403319 | L17: 0.07452576 | M17: 0.066677965 | N17: 0.056966967 | O17: 0.04546062 | V17: Margin | W17: (%) | X17: =X16/X12 -> 0.14010106 | Y17: =Y16/Y12 -> 0.12738254 | Z17: =Z16/Z12 -> 0.11075959 | AA17: =AA16/AA12 -> 0.056718172 | AB17: =AB16/AB12 -> 0.037694656 | AC17: =AC16/AC12 -> 0.016957759 | AD17: =AD16/AD12 -> -0.0041788368 | AE17: =AE16/AE12 -> -0.024495194
E18: Growth | I18: -0.082165511 | J18: -0.15597878 | K18: -0.18528268 | L18: -0.072879485 | M18: -0.048049884 | N18: -0.090900792 | O18: -0.15643629 | V18: Growth | W18: (%) | Y18: =Y16/X16-1 -> -0.082165511 | Z18: =Z16/Y16-1 -> -0.15597878 | AA18: =AA16/Z16-1 -> -0.47144354 | AB18: =AB16/AA16-1 -> -0.31590831 | AC18: =AC16/AB16-1 -> -0.53991775 | AD18: =AD16/AC16-1 -> -1.2521028 | AE18: =AE16/AD16-1 -> 5.0377786
E21: Net Income | H21: 14974 | I21: 7153 | J21: 3855 | K21: 4066.4582 | L21: 1782.6121 | M21: 165.51769 | N21: -1638.5504 | O21: -3846.7319 | V21: Net Income | W21: (MM) | X21: =Model!H109 -> 14974 | Y21: =Model!I109 -> 7153 | Z21: =Model!J109 -> 3855 | AA21: =Model!K109 -> 1872.4085 | AB21: =Model!L109 -> -1300.1104 | AC21: =Model!M109 -> -4230.6469 | AD21: =Model!N109 -> -7360.1636 | AE21: =Model!O109 -> -10635.617
E22: Margin | H22: 0.15473324 | I22: 0.073221415 | J22: 0.040652979 | K22: 0.040110264 | L22: 0.016745833 | M22: 0.0014613561 | N22: -0.013595679 | O22: -0.030194469 | V22: Margin | W22: (%) | X22: =X21/X12 -> 0.15473324 | Y22: =Y21/Y12 -> 0.073221415 | Z22: =Z21/Z12 -> 0.040652979 | AA22: =AA21/AA12 -> 0.019130137 | AB22: =AB21/AB12 -> -0.012904493 | AC22: =AC21/AC12 -> -0.041060165 | AD22: =AD21/AD12 -> -0.069824953 | AE22: =AE21/AE12 -> -0.097956708
E23: Growth | I23: -0.52678937 | J23: -0.44479387 | K23: -0.013349932 | L23: -0.58250505 | M23: -0.91273315 | N23: NM | O23: NM | V23: Growth | W23: (%) | Y23: =IF(OR(Y22<=0,X22<=0),"NM",(Y22-X22)/X22) -> -0.52678937 | Z23: =IF(OR(Z22<=0,Y22<=0),"NM",(Z22-Y22)/Y22) -> -0.44479387 | AA23: =IF(OR(AA22<=0,Z22<=0),"NM",(AA22-Z22)/Z22) -> -0.5294284 | AB23: =IF(OR(AB22<=0,AA22<=0),"NM",(AB22-AA22)/AA22) -> NM | AC23: =IF(OR(AC22<=0,AB22<=0),"NM",(AC22-AB22)/AB22) -> NM | AD23: =IF(OR(AD22<=0,AC22<=0),"NM",(AD22-AC22)/AC22) -> NM | AE23: =IF(OR(AE22<=0,AD22<=0),"NM",(AE22-AD22)/AD22) -> NM
C26: SUMMARY VALUES - BEST CASE
K27: Projected
D28: ($ Millions) | F28: Trend | H28: =H7 -> 2023 | I28: =I7 -> 2024 | J28: =J7 -> 2025 | K28: =K7 -> 2026 | L28: =L7 -> 2027 | M28: =M7 -> 2028 | N28: =N7 -> 2029 | O28: =O7 -> 2030
D31: Income Statement Items
E33: Net Revenue | H33: 96773 | I33: 97690 | J33: 94827 | K33: 106388.51 | L33: 113985.9 | M33: 123785.53 | N33: 134485.18 | O33: 140889.82
E34: Growth | I34: 0.0094757835 | J34: -0.029306992 | K34: 0.12192208 | L34: 0.07141177 | M34: 0.085972337 | N34: 0.086436997 | O34: 0.047623412
E37: EBITDA | H37: 13558 | I37: 12444 | J37: 10503 | K37: 12066.448 | L37: 12606.096 | M37: 13567.465 | N37: 14343.245 | O37: 13652.361
E38: Margin | H38: 0.14010106 | I38: 0.12738254 | J38: 0.11075959 | K38: 0.11341872 | L38: 0.11059347 | M38: 0.10960461 | N38: 0.10665298 | O38: 0.096900974
E39: Growth | I39: -0.082165511 | J39: -0.15597878 | K39: 0.14885725 | L39: 0.044723019 | M39: 0.076262221 | N39: 0.057179442 | O39: -0.048167869
E42: Net Income | H42: 14974 | I42: 7153 | J42: 3855 | K42: 6628.3725 | L42: 5269.8521 | M42: 4740.4851 | N42: 4186.779 | O42: 2550.5446
E43: Margin | H43: 0.15473324 | I43: 0.073221415 | J43: 0.040652979 | K43: 0.062303465 | L43: 0.046232493 | M43: 0.038295955 | N43: 0.031131898 | O43: 0.018103114
E44: Growth | I44: -0.52678937 | J44: -0.44479387 | K44: 0.53256828 | L44: -0.25794669 | M44: -0.17166579 | N44: -0.18707085 | O44: -0.41850272
C47: SUMMARY VALUES - WORST CASE
K48: Projected
D49: ($ Millions) | F49: Trend | H49: =H28 -> 2023 | I49: =I28 -> 2024 | J49: =J28 -> 2025 | K49: =K28 -> 2026 | L49: =L28 -> 2027 | M49: =M28 -> 2028 | N49: =N28 -> 2029 | O49: =O28 -> 2030
D52: Income Statement Items
E53: Net Revenue | H53: 96773 | I53: 97690 | J53: 94827 | K53: 97877.423 | L53: 100748.66 | M53: 103035.31 | N53: 105408.79 | O53: 108574.67
E54: Growth | I54: 0.0094757835 | J54: -0.029306992 | K54: 0.032168293 | L54: 0.029335033 | M54: 0.022696592 | N54: 0.023035559 | O54: 0.030034355
E57: EBITDA | H57: 13558 | I57: 12444 | J57: 10503 | K57: 5551.4285 | L57: 3797.6861 | M57: 1747.248 | N57: -440.48612 | O57: -2659.5577
E58: Margin | H58: 0.14010106 | I58: 0.12738254 | J58: 0.11075959 | K58: 0.056718172 | L58: 0.037694656 | M58: 0.016957759 | N58: -0.0041788368 | O58: -0.024495194
E59: Growth | I59: -0.082165511 | J59: -0.15597878 | K59: -0.47144354 | L59: -0.31590831 | M59: -0.53991775 | N59: -1.2521028 | O59: 5.0377786
E62: Net Income | H62: 14974 | I62: 7153 | J62: 3855 | K62: 1872.4085 | L62: -1300.1104 | M62: -4230.6469 | N62: -7360.1636 | O62: -10635.617
E63: Margin | H63: 0.15473324 | I63: 0.073221415 | J63: 0.040652979 | K63: 0.019130137 | L63: -0.012904493 | M63: -0.041060165 | N63: -0.069824953 | O63: -0.097956708
E64: Growth | I64: -0.52678937 | J64: -0.44479387 | K64: -0.5294284 | L64: NM | M64: NM | N64: NM | O64: NM

Sheet 備註
A1: 1.在Assumption-Cost的假設中，由於未能從財報中取得數據，所以此處數據由25年公布的相關COGS反推得到，可能存在不嚴謹處
A2: 2.在關於利率的假設中，決定採用平均餘額倒推得到，其中利息收入從財報中得到
A3: 3.Tesla 2025 年披露的其他 recourse debt 利率大約在 4.70%–5.75%,這裡決定採用更一般情況的（類平均）5.5%作為利率
A4: 4.關於Others：這裡是是所有汽車業務以外的總和，統一使用5%的簡化年增長率[Revenue]，Cost也為5%，R&D為10%
A5: 5.關於CAPEX的來源，Tesla 管理層在 2026 Q2 更新中表示全年 CapEx > $25bn，此處為以此作根據作出的財務判斷假設
A6: 6.關於Accounts Payable的來源，Tesla在10-K中提到： "Better working capital management resulting in shorter days sales outstanding than days payable outstanding.", 而根據25年財報推算出此值約為63，此處為以此作根據作出的財務判斷假設
A7: 7.Tesla 2023 因為釋放大量 deferred tax valuation allowance，所以此年份在Model的deferred tax benefit 高達 $6.349bn
A8: 8.關於預測淨利潤在後期為負的說明：由於[備註3]表明Tesla公開表示將投入大於$25bn的CAPEX，這部分投入未能充分及時地轉換為生產能力，與此同時折舊使得淨利潤承壓，故淨利潤將在預測中逐漸表現為負
A9: 9.關於本模型最核心的結構說明：對於Tesla的核心Automotive Sales業務， 採用嚴格的價格*銷量預測法（包含折舊，成本變化等一系列輔表）；對於除此以外的業務，統一歸納為Others並採用固定的預測增長率，詳細可以查看[備註4]
